Workbook

Sheet cbm_aug_2022
B1: Number of Announced Closures
A2: =IF(EDATE(DATE(2022,6,1), row(A2))<TODAY(), EDATE(DATE(2022,6,1), Row(A2)), "") -> 44774 | B2: =IF(A2="","",COUNTIFS(All_closures!$J$2:$J$1005, ">="& EDATE(DATE(2022,6,1), row(B2)),All_closures!$J$2:$J$1005, "<"& EDATE(DATE(2022,7,1), row(B2)))) -> 2
A3: =IF(EDATE(DATE(2022,6,1), row(A3))<TODAY(), EDATE(DATE(2022,6,1), Row(A3)), "") -> 44805 | B3: =IF(A3="","",COUNTIFS(All_closures!$J$2:$J$1005, ">="& EDATE(DATE(2022,6,1), row(B3)),All_closures!$J$2:$J$1005, "<"& EDATE(DATE(2022,7,1), row(B3)))) -> 0
A4: =IF(EDATE(DATE(2022,6,1), row(A4))<TODAY(), EDATE(DATE(2022,6,1), Row(A4)), "") -> 44835 | B4: =IF(A4="","",COUNTIFS(All_closures!$J$2:$J$1005, ">="& EDATE(DATE(2022,6,1), row(B4)),All_closures!$J$2:$J$1005, "<"& EDATE(DATE(2022,7,1), row(B4)))) -> 1
A5: =IF(EDATE(DATE(2022,6,1), row(A5))<TODAY(), EDATE(DATE(2022,6,1), Row(A5)), "") -> 44866 | B5: =IF(A5="","",COUNTIFS(All_closures!$J$2:$J$1005, ">="& EDATE(DATE(2022,6,1), row(B5)),All_closures!$J$2:$J$1005, "<"& EDATE(DATE(2022,7,1), row(B5)))) -> 1
A6: =IF(EDATE(DATE(2022,6,1), row(A6))<TODAY(), EDATE(DATE(2022,6,1), Row(A6)), "") -> 44896 | B6: =IF(A6="","",COUNTIFS(All_closures!$J$2:$J$1005, ">="& EDATE(DATE(2022,6,1), row(B6)),All_closures!$J$2:$J$1005, "<"& EDATE(DATE(2022,7,1), row(B6)))) -> 0
A7: =IF(EDATE(DATE(2022,6,1), row(A7))<TODAY(), EDATE(DATE(2022,6,1), Row(A7)), "") -> 44927 | B7: =IF(A7="","",COUNTIFS(All_closures!$J$2:$J$1005, ">="& EDATE(DATE(2022,6,1), row(B7)),All_closures!$J$2:$J$1005, "<"& EDATE(DATE(2022,7,1), row(B7)))) -> 8
A8: =IF(EDATE(DATE(2022,6,1), row(A8))<TODAY(), EDATE(DATE(2022,6,1), Row(A8)), "") -> 44958 | B8: =IF(A8="","",COUNTIFS(All_closures!$J$2:$J$1005, ">="& EDATE(DATE(2022,6,1), row(B8)),All_closures!$J$2:$J$1005, "<"& EDATE(DATE(2022,7,1), row(B8)))) -> 20
A9: =IF(EDATE(DATE(2022,6,1), row(A9))<TODAY(), EDATE(DATE(2022,6,1), Row(A9)), "") -> 44986 | B9: =IF(A9="","",COUNTIFS(All_closures!$J$2:$J$1005, ">="& EDATE(DATE(2022,6,1), row(B9)),All_closures!$J$2:$J$1005, "<"& EDATE(DATE(2022,7,1), row(B9)))) -> 5
A10: =IF(EDATE(DATE(2022,6,1), row(A10))<TODAY(), EDATE(DATE(2022,6,1), Row(A10)), "") -> 45017 | B10: =IF(A10="","",COUNTIFS(All_closures!$J$2:$J$1005, ">="& EDATE(DATE(2022,6,1), row(B10)),All_closures!$J$2:$J$1005, "<"& EDATE(DATE(2022,7,1), row(B10)))) -> 6
A11: =IF(EDATE(DATE(2022,6,1), row(A11))<TODAY(), EDATE(DATE(2022,6,1), Row(A11)), "") -> 45047 | B11: =IF(A11="","",COUNTIFS(All_closures!$J$2:$J$1005, ">="& EDATE(DATE(2022,6,1), row(B11)),All_closures!$J$2:$J$1005, "<"& EDATE(DATE(2022,7,1), row(B11)))) -> 5
A12: =IF(EDATE(DATE(2022,6,1), row(A12))<TODAY(), EDATE(DATE(2022,6,1), Row(A12)), "") -> 45078 | B12: =IF(A12="","",COUNTIFS(All_closures!$J$2:$J$1005, ">="& EDATE(DATE(2022,6,1), row(B12)),All_closures!$J$2:$J$1005, "<"& EDATE(DATE(2022,7,1), row(B12)))) -> 3
A13: =IF(EDATE(DATE(2022,6,1), row(A13))<TODAY(), EDATE(DATE(2022,6,1), Row(A13)), "") -> 45108 | B13: =IF(A13="","",COUNTIFS(All_closures!$J$2:$J$1005, ">="& EDATE(DATE(2022,6,1), row(B13)),All_closures!$J$2:$J$1005, "<"& EDATE(DATE(2022,7,1), row(B13)))) -> 3 | C13: =SUM(B2:B13) -> 54
A14: =IF(EDATE(DATE(2022,6,1), row(A14))<TODAY(), EDATE(DATE(2022,6,1), Row(A14)), "") -> 45139 | B14: =IF(A14="","",COUNTIFS(All_closures!$J$2:$J$1005, ">="& EDATE(DATE(2022,6,1), row(B14)),All_closures!$J$2:$J$1005, "<"& EDATE(DATE(2022,7,1), row(B14)))) -> 2
A15: =IF(EDATE(DATE(2022,6,1), row(A15))<TODAY(), EDATE(DATE(2022,6,1), Row(A15)), "") -> 45170 | B15: =IF(A15="","",COUNTIFS(All_closures!$J$2:$J$1005, ">="& EDATE(DATE(2022,6,1), row(B15)),All_closures!$J$2:$J$1005, "<"& EDATE(DATE(2022,7,1), row(B15)))) -> 2
A16: =IF(EDATE(DATE(2022,6,1), row(A16))<TODAY(), EDATE(DATE(2022,6,1), Row(A16)), "") -> 45200 | B16: =IF(A16="","",COUNTIFS(All_closures!$J$2:$J$1005, ">="& EDATE(DATE(2022,6,1), row(B16)),All_closures!$J$2:$J$1005, "<"& EDATE(DATE(2022,7,1), row(B16)))) -> 5
A17: =IF(EDATE(DATE(2022,6,1), row(A17))<TODAY(), EDATE(DATE(2022,6,1), Row(A17)), "") -> 45231 | B17: =IF(A17="","",COUNTIFS(All_closures!$J$2:$J$1005, ">="& EDATE(DATE(2022,6,1), row(B17)),All_closures!$J$2:$J$1005, "<"& EDATE(DATE(2022,7,1), row(B17)))) -> 1
A18: =IF(EDATE(DATE(2022,6,1), row(A18))<TODAY(), EDATE(DATE(2022,6,1), Row(A18)), "") -> 45261 | B18: =IF(A18="","",COUNTIFS(All_closures!$J$2:$J$1005, ">="& EDATE(DATE(2022,6,1), row(B18)),All_closures!$J$2:$J$1005, "<"& EDATE(DATE(2022,7,1), row(B18)))) -> 3
A19: =IF(EDATE(DATE(2022,6,1), row(A19))<TODAY(), EDATE(DATE(2022,6,1), Row(A19)), "") -> 45292 | B19: =IF(A19="","",COUNTIFS(All_closures!$J$2:$J$1005, ">="& EDATE(DATE(2022,6,1), row(B19)),All_closures!$J$2:$J$1005, "<"& EDATE(DATE(2022,7,1), row(B19)))) -> 6
A20: =IF(EDATE(DATE(2022,6,1), row(A20))<TODAY(), EDATE(DATE(2022,6,1), Row(A20)), "") -> 45323 | B20: =IF(A20="","",COUNTIFS(All_closures!$J$2:$J$1005, ">="& EDATE(DATE(2022,6,1), row(B20)),All_closures!$J$2:$J$1005, "<"& EDATE(DATE(2022,7,1), row(B20)))) -> 6
A21: =IF(EDATE(DATE(2022,6,1), row(A21))<TODAY(), EDATE(DATE(2022,6,1), Row(A21)), "") -> 45352 | B21: =IF(A21="","",COUNTIFS(All_closures!$J$2:$J$1005, ">="& EDATE(DATE(2022,6,1), row(B21)),All_closures!$J$2:$J$1005, "<"& EDATE(DATE(2022,7,1), row(B21)))) -> 7
A22: =IF(EDATE(DATE(2022,6,1), row(A22))<TODAY(), EDATE(DATE(2022,6,1), Row(A22)), "") -> 45383 | B22: =IF(A22="","",COUNTIFS(All_closures!$J$2:$J$1005, ">="& EDATE(DATE(2022,6,1), row(B22)),All_closures!$J$2:$J$1005, "<"& EDATE(DATE(2022,7,1), row(B22)))) -> 10
A23: =IF(EDATE(DATE(2022,6,1), row(A23))<TODAY(), EDATE(DATE(2022,6,1), Row(A23)), "") -> 45413 | B23: =IF(A23="","",COUNTIFS(All_closures!$J$2:$J$1005, ">="& EDATE(DATE(2022,6,1), row(B23)),All_closures!$J$2:$J$1005, "<"& EDATE(DATE(2022,7,1), row(B23)))) -> 11
A24: =IF(EDATE(DATE(2022,6,1), row(A24))<TODAY(), EDATE(DATE(2022,6,1), Row(A24)), "") -> 45444 | B24: =IF(A24="","",COUNTIFS(All_closures!$J$2:$J$1005, ">="& EDATE(DATE(2022,6,1), row(B24)),All_closures!$J$2:$J$1005, "<"& EDATE(DATE(2022,7,1), row(B24)))) -> 4
A25: =IF(EDATE(DATE(2022,6,1), row(A25))<TODAY(), EDATE(DATE(2022,6,1), Row(A25)), "") -> 45474 | B25: =IF(A25="","",COUNTIFS(All_closures!$J$2:$J$1005, ">="& EDATE(DATE(2022,6,1), row(B25)),All_closures!$J$2:$J$1005, "<"& EDATE(DATE(2022,7,1), row(B25)))) -> 3 | C25: =SUM(B14:B25) -> 60
A26: =IF(EDATE(DATE(2022,6,1), row(A26))<TODAY(), EDATE(DATE(2022,6,1), Row(A26)), "") -> 45505 | B26: =IF(A26="","",COUNTIFS(All_closures!$J$2:$J$1005, ">="& EDATE(DATE(2022,6,1), row(B26)),All_closures!$J$2:$J$1005, "<"& EDATE(DATE(2022,7,1), row(B26)))) -> 2
A27: =IF(EDATE(DATE(2022,6,1), row(A27))<TODAY(), EDATE(DATE(2022,6,1), Row(A27)), "") -> 45536 | B27: =IF(A27="","",COUNTIFS(All_closures!$J$2:$J$1005, ">="& EDATE(DATE(2022,6,1), row(B27)),All_closures!$J$2:$J$1005, "<"& EDATE(DATE(2022,7,1), row(B27)))) -> 4
A28: =IF(EDATE(DATE(2022,6,1), row(A28))<TODAY(), EDATE(DATE(2022,6,1), Row(A28)), "") -> 45566 | B28: =IF(A28="","",COUNTIFS(All_closures!$J$2:$J$1005, ">="& EDATE(DATE(2022,6,1), row(B28)),All_closures!$J$2:$J$1005, "<"& EDATE(DATE(2022,7,1), row(B28)))) -> 1
A29: =IF(EDATE(DATE(2022,6,1), row(A29))<TODAY(), EDATE(DATE(2022,6,1), Row(A29)), "") -> 45597 | B29: =IF(A29="","",COUNTIFS(All_closures!$J$2:$J$1005, ">="& EDATE(DATE(2022,6,1), row(B29)),All_closures!$J$2:$J$1005, "<"& EDATE(DATE(2022,7,1), row(B29)))) -> 1
A30: =IF(EDATE(DATE(2022,6,1), row(A30))<TODAY(), EDATE(DATE(2022,6,1), Row(A30)), "") -> 45627 | B30: =IF(A30="","",COUNTIFS(All_closures!$J$2:$J$1005, ">="& EDATE(DATE(2022,6,1), row(B30)),All_closures!$J$2:$J$1005, "<"& EDATE(DATE(2022,7,1), row(B30)))) -> 5
A31: =IF(EDATE(DATE(2022,6,1), row(A31))<TODAY(), EDATE(DATE(2022,6,1), Row(A31)), "") -> 45658 | B31: =IF(A31="","",COUNTIFS(All_closures!$J$2:$J$1005, ">="& EDATE(DATE(2022,6,1), row(B31)),All_closures!$J$2:$J$1005, "<"& EDATE(DATE(2022,7,1), row(B31)))) -> 9
A32: =IF(EDATE(DATE(2022,6,1), row(A32))<TODAY(), EDATE(DATE(2022,6,1), Row(A32)), "") -> 45689 | B32: =IF(A32="","",COUNTIFS(All_closures!$J$2:$J$1005, ">="& EDATE(DATE(2022,6,1), row(B32)),All_closures!$J$2:$J$1005, "<"& EDATE(DATE(2022,7,1), row(B32)))) -> 10
A33: =IF(EDATE(DATE(2022,6,1), row(A33))<TODAY(), EDATE(DATE(2022,6,1), Row(A33)), "") -> 45717 | B33: =IF(A33="","",COUNTIFS(All_closures!$J$2:$J$1005, ">="& EDATE(DATE(2022,6,1), row(B33)),All_closures!$J$2:$J$1005, "<"& EDATE(DATE(2022,7,1), row(B33)))) -> 6
A34: =IF(EDATE(DATE(2022,6,1), row(A34))<TODAY(), EDATE(DATE(2022,6,1), Row(A34)), "") -> 45748 | B34: =IF(A34="","",COUNTIFS(All_closures!$J$2:$J$1005, ">="& EDATE(DATE(2022,6,1), row(B34)),All_closures!$J$2:$J$1005, "<"& EDATE(DATE(2022,7,1), row(B34)))) -> 5
A35: =IF(EDATE(DATE(2022,6,1), row(A35))<TODAY(), EDATE(DATE(2022,6,1), Row(A35)), "") -> 45778 | B35: =IF(A35="","",COUNTIFS(All_closures!$J$2:$J$1005, ">="& EDATE(DATE(2022,6,1), row(B35)),All_closures!$J$2:$J$1005, "<"& EDATE(DATE(2022,7,1), row(B35)))) -> 4
A36: =IF(EDATE(DATE(2022,6,1), row(A36))<TODAY(), EDATE(DATE(2022,6,1), Row(A36)), "") -> 45809 | B36: =IF(A36="","",COUNTIFS(All_closures!$J$2:$J$1005, ">="& EDATE(DATE(2022,6,1), row(B36)),All_closures!$J$2:$J$1005, "<"& EDATE(DATE(2022,7,1), row(B36)))) -> 4
A37: =IF(EDATE(DATE(2022,6,1), row(A37))<TODAY(), EDATE(DATE(2022,6,1), Row(A37)), "") -> 45839 | B37: =IF(A37="","",COUNTIFS(All_closures!$J$2:$J$1005, ">="& EDATE(DATE(2022,6,1), row(B37)),All_closures!$J$2:$J$1005, "<"& EDATE(DATE(2022,7,1), row(B37)))) -> 1
... A50: =IF(EDATE(DATE(2022,6,1), row(A50))<TODAY(), EDATE(DATE(2022,6,1), Row(A50)), "") | B50: =IF(A50="","",COUNTIFS(All_closures!$J$2:$J$1005, ">="& EDATE(DATE(2022,6,1), row(B50)),All_closures!$J$2:$J$1005, "<"& EDATE(DATE(2022,7,1), row(B50))))

Sheet cbm_aug_2023
B1: Number of Announced Closures
A2: =IF(EDATE(DATE(2023,6,1), row(A2))<TODAY(), EDATE(DATE(2023,6,1), Row(A2)), "") -> 45139 | B2: =IF(A2="","",COUNTIFS(All_closures!$J$2:$J$1005, ">="& EDATE(DATE(2023,6,1), row(B2)),All_closures!$J$2:$J$1005, "<"& EDATE(DATE(2023,7,1), row(B2)))) -> 2
A3: =IF(EDATE(DATE(2023,6,1), row(A3))<TODAY(), EDATE(DATE(2023,6,1), Row(A3)), "") -> 45170 | B3: =IF(A3="","",COUNTIFS(All_closures!$J$2:$J$1005, ">="& EDATE(DATE(2023,6,1), row(B3)),All_closures!$J$2:$J$1005, "<"& EDATE(DATE(2023,7,1), row(B3)))) -> 2
A4: =IF(EDATE(DATE(2023,6,1), row(A4))<TODAY(), EDATE(DATE(2023,6,1), Row(A4)), "") -> 45200 | B4: =IF(A4="","",COUNTIFS(All_closures!$J$2:$J$1005, ">="& EDATE(DATE(2023,6,1), row(B4)),All_closures!$J$2:$J$1005, "<"& EDATE(DATE(2023,7,1), row(B4)))) -> 5
A5: =IF(EDATE(DATE(2023,6,1), row(A5))<TODAY(), EDATE(DATE(2023,6,1), Row(A5)), "") -> 45231 | B5: =IF(A5="","",COUNTIFS(All_closures!$J$2:$J$1005, ">="& EDATE(DATE(2023,6,1), row(B5)),All_closures!$J$2:$J$1005, "<"& EDATE(DATE(2023,7,1), row(B5)))) -> 1
A6: =IF(EDATE(DATE(2023,6,1), row(A6))<TODAY(), EDATE(DATE(2023,6,1), Row(A6)), "") -> 45261 | B6: =IF(A6="","",COUNTIFS(All_closures!$J$2:$J$1005, ">="& EDATE(DATE(2023,6,1), row(B6)),All_closures!$J$2:$J$1005, "<"& EDATE(DATE(2023,7,1), row(B6)))) -> 3
A7: =IF(EDATE(DATE(2023,6,1), row(A7))<TODAY(), EDATE(DATE(2023,6,1), Row(A7)), "") -> 45292 | B7: =IF(A7="","",COUNTIFS(All_closures!$J$2:$J$1005, ">="& EDATE(DATE(2023,6,1), row(B7)),All_closures!$J$2:$J$1005, "<"& EDATE(DATE(2023,7,1), row(B7)))) -> 6
A8: =IF(EDATE(DATE(2023,6,1), row(A8))<TODAY(), EDATE(DATE(2023,6,1), Row(A8)), "") -> 45323 | B8: =IF(A8="","",COUNTIFS(All_closures!$J$2:$J$1005, ">="& EDATE(DATE(2023,6,1), row(B8)),All_closures!$J$2:$J$1005, "<"& EDATE(DATE(2023,7,1), row(B8)))) -> 6
A9: =IF(EDATE(DATE(2023,6,1), row(A9))<TODAY(), EDATE(DATE(2023,6,1), Row(A9)), "") -> 45352 | B9: =IF(A9="","",COUNTIFS(All_closures!$J$2:$J$1005, ">="& EDATE(DATE(2023,6,1), row(B9)),All_closures!$J$2:$J$1005, "<"& EDATE(DATE(2023,7,1), row(B9)))) -> 7
A10: =IF(EDATE(DATE(2023,6,1), row(A10))<TODAY(), EDATE(DATE(2023,6,1), Row(A10)), "") -> 45383 | B10: =IF(A10="","",COUNTIFS(All_closures!$J$2:$J$1005, ">="& EDATE(DATE(2023,6,1), row(B10)),All_closures!$J$2:$J$1005, "<"& EDATE(DATE(2023,7,1), row(B10)))) -> 10
A11: =IF(EDATE(DATE(2023,6,1), row(A11))<TODAY(), EDATE(DATE(2023,6,1), Row(A11)), "") -> 45413 | B11: =IF(A11="","",COUNTIFS(All_closures!$J$2:$J$1005, ">="& EDATE(DATE(2023,6,1), row(B11)),All_closures!$J$2:$J$1005, "<"& EDATE(DATE(2023,7,1), row(B11)))) -> 11
A12: =IF(EDATE(DATE(2023,6,1), row(A12))<TODAY(), EDATE(DATE(2023,6,1), Row(A12)), "") -> 45444 | B12: =IF(A12="","",COUNTIFS(All_closures!$J$2:$J$1005, ">="& EDATE(DATE(2023,6,1), row(B12)),All_closures!$J$2:$J$1005, "<"& EDATE(DATE(2023,7,1), row(B12)))) -> 4
A13: =IF(EDATE(DATE(2023,6,1), row(A13))<TODAY(), EDATE(DATE(2023,6,1), Row(A13)), "") -> 45474 | B13: =IF(A13="","",COUNTIFS(All_closures!$J$2:$J$1005, ">="& EDATE(DATE(2023,6,1), row(B13)),All_closures!$J$2:$J$1005, "<"& EDATE(DATE(2023,7,1), row(B13)))) -> 3
A35: =IF(EDATE(DATE(2023,6,1), row(A35))<TODAY(), EDATE(DATE(2023,6,1), Row(A35)), "") -> 46143
A36: =IF(EDATE(DATE(2023,6,1), row(A36))<TODAY(), EDATE(DATE(2023,6,1), Row(A36)), "") -> 46174
A37: =IF(EDATE(DATE(2023,6,1), row(A37))<TODAY(), EDATE(DATE(2023,6,1), Row(A37)), "") -> 46204
A38: =IF(EDATE(DATE(2023,6,1), row(A38))<TODAY(), EDATE(DATE(2023,6,1), Row(A38)), "")
A39: =IF(EDATE(DATE(2023,6,1), row(A39))<TODAY(), EDATE(DATE(2023,6,1), Row(A39)), "")
A40: =IF(EDATE(DATE(2023,6,1), row(A40))<TODAY(), EDATE(DATE(2023,6,1), Row(A40)), "")
A41: =IF(EDATE(DATE(2023,6,1), row(A41))<TODAY(), EDATE(DATE(2023,6,1), Row(A41)), "") | B41: =IF(A41="","",COUNTIFS(All_closures!$J$2:$J$1005, ">="& EDATE(DATE(2023,6,1), row(B41)),All_closures!$J$2:$J$1005, "<"& EDATE(DATE(2023,7,1), row(B41))))
A42: =IF(EDATE(DATE(2023,6,1), row(A42))<TODAY(), EDATE(DATE(2023,6,1), Row(A42)), "") | B42: =IF(A42="","",COUNTIFS(All_closures!$J$2:$J$1005, ">="& EDATE(DATE(2023,6,1), row(B42)),All_closures!$J$2:$J$1005, "<"& EDATE(DATE(2023,7,1), row(B42))))
A43: =IF(EDATE(DATE(2023,6,1), row(A43))<TODAY(), EDATE(DATE(2023,6,1), Row(A43)), "") | B43: =IF(A43="","",COUNTIFS(All_closures!$J$2:$J$1005, ">="& EDATE(DATE(2023,6,1), row(B43)),All_closures!$J$2:$J$1005, "<"& EDATE(DATE(2023,7,1), row(B43))))
A44: =IF(EDATE(DATE(2023,6,1), row(A44))<TODAY(), EDATE(DATE(2023,6,1), Row(A44)), "") | B44: =IF(A44="","",COUNTIFS(All_closures!$J$2:$J$1005, ">="& EDATE(DATE(2023,6,1), row(B44)),All_closures!$J$2:$J$1005, "<"& EDATE(DATE(2023,7,1), row(B44))))
A45: =IF(EDATE(DATE(2023,6,1), row(A45))<TODAY(), EDATE(DATE(2023,6,1), Row(A45)), "") | B45: =IF(A45="","",COUNTIFS(All_closures!$J$2:$J$1005, ">="& EDATE(DATE(2023,6,1), row(B45)),All_closures!$J$2:$J$1005, "<"& EDATE(DATE(2023,7,1), row(B45))))
A46: =IF(EDATE(DATE(2023,6,1), row(A46))<TODAY(), EDATE(DATE(2023,6,1), Row(A46)), "") | B46: =IF(A46="","",COUNTIFS(All_closures!$J$2:$J$1005, ">="& EDATE(DATE(2023,6,1), row(B46)),All_closures!$J$2:$J$1005, "<"& EDATE(DATE(2023,7,1), row(B46))))
A47: =IF(EDATE(DATE(2023,6,1), row(A47))<TODAY(), EDATE(DATE(2023,6,1), Row(A47)), "") | B47: =IF(A47="","",COUNTIFS(All_closures!$J$2:$J$1005, ">="& EDATE(DATE(2023,6,1), row(B47)),All_closures!$J$2:$J$1005, "<"& EDATE(DATE(2023,7,1), row(B47))))
A48: =IF(EDATE(DATE(2023,6,1), row(A48))<TODAY(), EDATE(DATE(2023,6,1), Row(A48)), "") | B48: =IF(A48="","",COUNTIFS(All_closures!$J$2:$J$1005, ">="& EDATE(DATE(2023,6,1), row(B48)),All_closures!$J$2:$J$1005, "<"& EDATE(DATE(2023,7,1), row(B48))))
A49: =IF(EDATE(DATE(2023,6,1), row(A49))<TODAY(), EDATE(DATE(2023,6,1), Row(A49)), "") | B49: =IF(A49="","",COUNTIFS(All_closures!$J$2:$J$1005, ">="& EDATE(DATE(2023,6,1), row(B49)),All_closures!$J$2:$J$1005, "<"& EDATE(DATE(2023,7,1), row(B49))))
A50: =IF(EDATE(DATE(2023,6,1), row(A50))<TODAY(), EDATE(DATE(2023,6,1), Row(A50)), "") | B50: =IF(A50="","",COUNTIFS(All_closures!$J$2:$J$1005, ">="& EDATE(DATE(2023,6,1), row(B50)),All_closures!$J$2:$J$1005, "<"& EDATE(DATE(2023,7,1), row(B50))))
A51: =IF(EDATE(DATE(2023,6,1), row(A51))<TODAY(), EDATE(DATE(2023,6,1), Row(A51)), "") | B51: =IF(A51="","",COUNTIFS(All_closures!$J$2:$J$1005, ">="& EDATE(DATE(2023,6,1), row(B51)),All_closures!$J$2:$J$1005, "<"& EDATE(DATE(2023,7,1), row(B51))))
A52: =IF(EDATE(DATE(2023,6,1), row(A52))<TODAY(), EDATE(DATE(2023,6,1), Row(A52)), "") | B52: =IF(A52="","",COUNTIFS(All_closures!$J$2:$J$1005, ">="& EDATE(DATE(2023,6,1), row(B52)),All_closures!$J$2:$J$1005, "<"& EDATE(DATE(2023,7,1), row(B52))))
... A61: =IF(EDATE(DATE(2023,6,1), row(A61))<TODAY(), EDATE(DATE(2023,6,1), Row(A61)), "") | B61: =IF(A61="","",COUNTIFS(All_closures!$J$2:$J$1005, ">="& EDATE(DATE(2023,6,1), row(B61)),All_closures!$J$2:$J$1005, "<"& EDATE(DATE(2023,7,1), row(B61))))

Sheet cbm_aug_2024
B1: Number of Announced Closures
A2: =IF(EDATE(DATE(2024,6,1), row(A2))<TODAY(), EDATE(DATE(2024,6,1), Row(A2)), "") -> 45505 | B2: =IF(A2="","",COUNTIFS(All_closures!$J$2:$J$1005, ">="& EDATE(DATE(2024,6,1), row(B2)),All_closures!$J$2:$J$1005, "<"& EDATE(DATE(2024,7,1), row(B2)))) -> 2
A3: =IF(EDATE(DATE(2024,6,1), row(A3))<TODAY(), EDATE(DATE(2024,6,1), Row(A3)), "") -> 45536 | B3: =IF(A3="","",COUNTIFS(All_closures!$J$2:$J$1005, ">="& EDATE(DATE(2024,6,1), row(B3)),All_closures!$J$2:$J$1005, "<"& EDATE(DATE(2024,7,1), row(B3)))) -> 4
A4: =IF(EDATE(DATE(2024,6,1), row(A4))<TODAY(), EDATE(DATE(2024,6,1), Row(A4)), "") -> 45566 | B4: =IF(A4="","",COUNTIFS(All_closures!$J$2:$J$1005, ">="& EDATE(DATE(2024,6,1), row(B4)),All_closures!$J$2:$J$1005, "<"& EDATE(DATE(2024,7,1), row(B4)))) -> 1
A5: =IF(EDATE(DATE(2024,6,1), row(A5))<TODAY(), EDATE(DATE(2024,6,1), Row(A5)), "") -> 45597 | B5: =IF(A5="","",COUNTIFS(All_closures!$J$2:$J$1005, ">="& EDATE(DATE(2024,6,1), row(B5)),All_closures!$J$2:$J$1005, "<"& EDATE(DATE(2024,7,1), row(B5)))) -> 1
A6: =IF(EDATE(DATE(2024,6,1), row(A6))<TODAY(), EDATE(DATE(2024,6,1), Row(A6)), "") -> 45627 | B6: =IF(A6="","",COUNTIFS(All_closures!$J$2:$J$1005, ">="& EDATE(DATE(2024,6,1), row(B6)),All_closures!$J$2:$J$1005, "<"& EDATE(DATE(2024,7,1), row(B6)))) -> 5
A7: =IF(EDATE(DATE(2024,6,1), row(A7))<TODAY(), EDATE(DATE(2024,6,1), Row(A7)), "") -> 45658 | B7: =IF(A7="","",COUNTIFS(All_closures!$J$2:$J$1005, ">="& EDATE(DATE(2024,6,1), row(B7)),All_closures!$J$2:$J$1005, "<"& EDATE(DATE(2024,7,1), row(B7)))) -> 9
A8: =IF(EDATE(DATE(2024,6,1), row(A8))<TODAY(), EDATE(DATE(2024,6,1), Row(A8)), "") -> 45689 | B8: =IF(A8="","",COUNTIFS(All_closures!$J$2:$J$1005, ">="& EDATE(DATE(2024,6,1), row(B8)),All_closures!$J$2:$J$1005, "<"& EDATE(DATE(2024,7,1), row(B8)))) -> 10
A9: =IF(EDATE(DATE(2024,6,1), row(A9))<TODAY(), EDATE(DATE(2024,6,1), Row(A9)), "") -> 45717 | B9: =IF(A9="","",COUNTIFS(All_closures!$J$2:$J$1005, ">="& EDATE(DATE(2024,6,1), row(B9)),All_closures!$J$2:$J$1005, "<"& EDATE(DATE(2024,7,1), row(B9)))) -> 6
A10: =IF(EDATE(DATE(2024,6,1), row(A10))<TODAY(), EDATE(DATE(2024,6,1), Row(A10)), "") -> 45748 | B10: =IF(A10="","",COUNTIFS(All_closures!$J$2:$J$1005, ">="& EDATE(DATE(2024,6,1), row(B10)),All_closures!$J$2:$J$1005, "<"& EDATE(DATE(2024,7,1), row(B10)))) -> 5
A11: =IF(EDATE(DATE(2024,6,1), row(A11))<TODAY(), EDATE(DATE(2024,6,1), Row(A11)), "") -> 45778 | B11: =IF(A11="","",COUNTIFS(All_closures!$J$2:$J$1005, ">="& EDATE(DATE(2024,6,1), row(B11)),All_closures!$J$2:$J$1005, "<"& EDATE(DATE(2024,7,1), row(B11)))) -> 4
A12: =IF(EDATE(DATE(2024,6,1), row(A12))<TODAY(), EDATE(DATE(2024,6,1), Row(A12)), "") -> 45809 | B12: =IF(A12="","",COUNTIFS(All_closures!$J$2:$J$1005, ">="& EDATE(DATE(2024,6,1), row(B12)),All_closures!$J$2:$J$1005, "<"& EDATE(DATE(2024,7,1), row(B12)))) -> 4
A13: =IF(EDATE(DATE(2024,6,1), row(A13))<TODAY(), EDATE(DATE(2024,6,1), Row(A13)), "") -> 45839 | B13: =IF(A13="","",COUNTIFS(All_closures!$J$2:$J$1005, ">="& EDATE(DATE(2024,6,1), row(B13)),All_closures!$J$2:$J$1005, "<"& EDATE(DATE(2024,7,1), row(B13)))) -> 1
A14: =IF(EDATE(DATE(2024,6,1), row(A14))<TODAY(), EDATE(DATE(2024,6,1), Row(A14)), "") -> 45870 | B14: =IF(A14="","",COUNTIFS(All_closures!$J$2:$J$1005, ">="& EDATE(DATE(2024,6,1), row(B14)),All_closures!$J$2:$J$1005, "<"& EDATE(DATE(2024,7,1), row(B14)))) -> 0
A15: =IF(EDATE(DATE(2024,6,1), row(A15))<TODAY(), EDATE(DATE(2024,6,1), Row(A15)), "") -> 45901
A16: =IF(EDATE(DATE(2024,6,1), row(A16))<TODAY(), EDATE(DATE(2024,6,1), Row(A16)), "") -> 45931 | B16: =IF(A16="","",COUNTIFS(All_closures!$J$2:$J$1005, ">="& EDATE(DATE(2024,6,1), row(B16)),All_closures!$J$2:$J$1005, "<"& EDATE(DATE(2024,7,1), row(B16)))) -> 2
A17: =IF(EDATE(DATE(2024,6,1), row(A17))<TODAY(), EDATE(DATE(2024,6,1), Row(A17)), "") -> 45962 | B17: =IF(A17="","",COUNTIFS(All_closures!$J$2:$J$1005, ">="& EDATE(DATE(2024,6,1), row(B17)),All_closures!$J$2:$J$1005, "<"& EDATE(DATE(2024,7,1), row(B17)))) -> 2
A18: =IF(EDATE(DATE(2024,6,1), row(A18))<TODAY(), EDATE(DATE(2024,6,1), Row(A18)), "") -> 45992 | B18: =IF(A18="","",COUNTIFS(All_closures!$J$2:$J$1005, ">="& EDATE(DATE(2024,6,1), row(B18)),All_closures!$J$2:$J$1005, "<"& EDATE(DATE(2024,7,1), row(B18)))) -> 2
A19: =IF(EDATE(DATE(2024,6,1), row(A19))<TODAY(), EDATE(DATE(2024,6,1), Row(A19)), "") -> 46023 | B19: =IF(A19="","",COUNTIFS(All_closures!$J$2:$J$1005, ">="& EDATE(DATE(2024,6,1), row(B19)),All_closures!$J$2:$J$1005, "<"& EDATE(DATE(2024,7,1), row(B19)))) -> 11
A20: =IF(EDATE(DATE(2024,6,1), row(A20))<TODAY(), EDATE(DATE(2024,6,1), Row(A20)), "") -> 46054 | B20: =IF(A20="","",COUNTIFS(All_closures!$J$2:$J$1005, ">="& EDATE(DATE(2024,6,1), row(B20)),All_closures!$J$2:$J$1005, "<"& EDATE(DATE(2024,7,1), row(B20)))) -> 12
A21: =IF(EDATE(DATE(2024,6,1), row(A21))<TODAY(), EDATE(DATE(2024,6,1), Row(A21)), "") -> 46082 | B21: =IF(A21="","",COUNTIFS(All_closures!$J$2:$J$1005, ">="& EDATE(DATE(2024,6,1), row(B21)),All_closures!$J$2:$J$1005, "<"& EDATE(DATE(2024,7,1), row(B21)))) -> 13
A22: =IF(EDATE(DATE(2024,6,1), row(A22))<TODAY(), EDATE(DATE(2024,6,1), Row(A22)), "") -> 46113 | B22: =IF(A22="","",COUNTIFS(All_closures!$J$2:$J$1005, ">="& EDATE(DATE(2024,6,1), row(B22)),All_closures!$J$2:$J$1005, "<"& EDATE(DATE(2024,7,1), row(B22)))) -> 1
A23: =IF(EDATE(DATE(2024,6,1), row(A23))<TODAY(), EDATE(DATE(2024,6,1), Row(A23)), "") -> 46143 | B23: =IF(A23="","",COUNTIFS(All_closures!$J$2:$J$1005, ">="& EDATE(DATE(2024,6,1), row(B23)),All_closures!$J$2:$J$1005, "<"& EDATE(DATE(2024,7,1), row(B23)))) -> 6
A24: =IF(EDATE(DATE(2024,6,1), row(A24))<TODAY(), EDATE(DATE(2024,6,1), Row(A24)), "") -> 46174 | B24: =IF(A24="","",COUNTIFS(All_closures!$J$2:$J$1005, ">="& EDATE(DATE(2024,6,1), row(B24)),All_closures!$J$2:$J$1005, "<"& EDATE(DATE(2024,7,1), row(B24)))) -> 13
A25: =IF(EDATE(DATE(2024,6,1), row(A25))<TODAY(), EDATE(DATE(2024,6,1), Row(A25)), "") -> 46204 | B25: =IF(A25="","",COUNTIFS(All_closures!$J$2:$J$1005, ">="& EDATE(DATE(2024,6,1), row(B25)),All_closures!$J$2:$J$1005, "<"& EDATE(DATE(2024,7,1), row(B25)))) -> 4
A26: =IF(EDATE(DATE(2024,6,1), row(A26))<TODAY(), EDATE(DATE(2024,6,1), Row(A26)), "") | B26: =IF(A26="","",COUNTIFS(All_closures!$J$2:$J$1005, ">="& EDATE(DATE(2024,6,1), row(B26)),All_closures!$J$2:$J$1005, "<"& EDATE(DATE(2024,7,1), row(B26))))
A27: =IF(EDATE(DATE(2024,6,1), row(A27))<TODAY(), EDATE(DATE(2024,6,1), Row(A27)), "") | B27: =IF(A27="","",COUNTIFS(All_closures!$J$2:$J$1005, ">="& EDATE(DATE(2023,6,1), row(B27)),All_closures!$J$2:$J$1005, "<"& EDATE(DATE(2023,7,1), row(B27))))
A28: =IF(EDATE(DATE(2023,6,1), row(A28))<TODAY(), EDATE(DATE(2023,6,1), Row(A28)), "") -> 45931 | B28: =IF(A28="","",COUNTIFS(All_closures!$J$2:$J$1005, ">="& EDATE(DATE(2023,6,1), row(B28)),All_closures!$J$2:$J$1005, "<"& EDATE(DATE(2023,7,1), row(B28)))) -> 2
A29: =IF(EDATE(DATE(2023,6,1), row(A29))<TODAY(), EDATE(DATE(2023,6,1), Row(A29)), "") -> 45962 | B29: =IF(A29="","",COUNTIFS(All_closures!$J$2:$J$1005, ">="& EDATE(DATE(2023,6,1), row(B29)),All_closures!$J$2:$J$1005, "<"& EDATE(DATE(2023,7,1), row(B29)))) -> 2
A30: =IF(EDATE(DATE(2023,6,1), row(A30))<TODAY(), EDATE(DATE(2023,6,1), Row(A30)), "") -> 45992 | B30: =IF(A30="","",COUNTIFS(All_closures!$J$2:$J$1005, ">="& EDATE(DATE(2023,6,1), row(B30)),All_closures!$J$2:$J$1005, "<"& EDATE(DATE(2023,7,1), row(B30)))) -> 2
A31: =IF(EDATE(DATE(2023,6,1), row(A31))<TODAY(), EDATE(DATE(2023,6,1), Row(A31)), "") -> 46023 | B31: =IF(A31="","",COUNTIFS(All_closures!$J$2:$J$1005, ">="& EDATE(DATE(2023,6,1), row(B31)),All_closures!$J$2:$J$1005, "<"& EDATE(DATE(2023,7,1), row(B31)))) -> 11
A32: =IF(EDATE(DATE(2023,6,1), row(A32))<TODAY(), EDATE(DATE(2023,6,1), Row(A32)), "") -> 46054 | B32: =IF(A32="","",COUNTIFS(All_closures!$J$2:$J$1005, ">="& EDATE(DATE(2023,6,1), row(B32)),All_closures!$J$2:$J$1005, "<"& EDATE(DATE(2023,7,1), row(B32)))) -> 12
A33: =IF(EDATE(DATE(2023,6,1), row(A33))<TODAY(), EDATE(DATE(2023,6,1), Row(A33)), "") -> 46082 | B33: =IF(A33="","",COUNTIFS(All_closures!$J$2:$J$1005, ">="& EDATE(DATE(2023,6,1), row(B33)),All_closures!$J$2:$J$1005, "<"& EDATE(DATE(2023,7,1), row(B33)))) -> 13
A34: =IF(EDATE(DATE(2023,6,1), row(A34))<TODAY(), EDATE(DATE(2023,6,1), Row(A34)), "") -> 46113 | B34: =IF(A34="","",COUNTIFS(All_closures!$J$2:$J$1005, ">="& EDATE(DATE(2023,6,1), row(B34)),All_closures!$J$2:$J$1005, "<"& EDATE(DATE(2023,7,1), row(B34)))) -> 1
A35: =IF(EDATE(DATE(2023,6,1), row(A35))<TODAY(), EDATE(DATE(2023,6,1), Row(A35)), "") -> 46143 | B35: =IF(A35="","",COUNTIFS(All_closures!$J$2:$J$1005, ">="& EDATE(DATE(2023,6,1), row(B35)),All_closures!$J$2:$J$1005, "<"& EDATE(DATE(2023,7,1), row(B35)))) -> 6
A36: =IF(EDATE(DATE(2023,6,1), row(A36))<TODAY(), EDATE(DATE(2023,6,1), Row(A36)), "") -> 46174 | B36: =IF(A36="","",COUNTIFS(All_closures!$J$2:$J$1005, ">="& EDATE(DATE(2023,6,1), row(B36)),All_closures!$J$2:$J$1005, "<"& EDATE(DATE(2023,7,1), row(B36)))) -> 13
A37: =IF(EDATE(DATE(2023,6,1), row(A37))<TODAY(), EDATE(DATE(2023,6,1), Row(A37)), "") -> 46204 | B37: =IF(A37="","",COUNTIFS(All_closures!$J$2:$J$1005, ">="& EDATE(DATE(2023,6,1), row(B37)),All_closures!$J$2:$J$1005, "<"& EDATE(DATE(2023,7,1), row(B37)))) -> 4
A38: =IF(EDATE(DATE(2023,6,1), row(A38))<TODAY(), EDATE(DATE(2023,6,1), Row(A38)), "") | B38: =IF(A38="","",COUNTIFS(All_closures!$J$2:$J$1005, ">="& EDATE(DATE(2023,6,1), row(B38)),All_closures!$J$2:$J$1005, "<"& EDATE(DATE(2023,7,1), row(B38))))
A39: =IF(EDATE(DATE(2023,6,1), row(A39))<TODAY(), EDATE(DATE(2023,6,1), Row(A39)), "") | B39: =IF(A39="","",COUNTIFS(All_closures!$J$2:$J$1005, ">="& EDATE(DATE(2023,6,1), row(B39)),All_closures!$J$2:$J$1005, "<"& EDATE(DATE(2023,7,1), row(B39))))
... A61: =IF(EDATE(DATE(2023,6,1), row(A61))<TODAY(), EDATE(DATE(2023,6,1), Row(A61)), "") | B61: =IF(A61="","",COUNTIFS(All_closures!$J$2:$J$1005, ">="& EDATE(DATE(2023,6,1), row(B61)),All_closures!$J$2:$J$1005, "<"& EDATE(DATE(2023,7,1), row(B61))))

Sheet All_openings
B1: Name | C1: Link | D1: Town | E1: State | F1: Region | G1: Type | H1: Date Reported | I1: Expected Opening Date | J1: Expected Enrollment | K1: Source/Links | L1: Notes | M1: Annual Tuition | N1: Tuition Notes | O1: Link | P1: Full Address | Q1: Estimated Tract Median Family Income | R1: Data Year | S1: Microschool?
A2: =row()-1 -> 1 | B2: Avenues Sillicon Valley | C2: https://www.asumag.com/facilities-management/business-finance/article/21238677/private-school-based-in-new-york-city-buys-property-in-san-jose-calif-plans-prek12-campus | D2: San Jose | E2: CA | F2: West | G2: Independent | H2: 43556 | I2: Fall 2022 | K2: https://www.sanjoseinside.com/news/exclusive-private-school-to-open-silicon-valley-campus/ | M2: 57500 | O2: https://www.avenues.org/sv/tuition-financial-aid | P2: 570 Meridian Ave San Jose, CA 95126 | Q2: 107689 | R2: 2021
A3: =row()-1 -> 2 | B3: Christo Rey Research Triangle High School | C3: https://dioceseofraleigh.org/news/cristo-rey-rtp-announces-jesuit-affiliation-planned-high-school | D3: Raleigh | E3: NC | F3: South | G3: Roman Catholic | H3: 43900 | I3: Fall 2021 | J3: 100 | K3: https://www.cristoreyrt.org/ | M3: 700 | N3: 70/month for 10 months. Sliding scale and work contributions | O3: https://www.cristoreyrt.org/apps/pages/index.jsp?uREC_ID=2126760&type=d&pREC_ID=2156787 | P3: 334 Blackwell Street, Durham, NC 27701 | Q3: 100474 | R3: 2020
A4: =row()-1 -> 3 | B4: All Saints Catholic Academy | C4: https://patch.com/connecticut/naugatuck/new-catholic-school-open-new-haven | D4: New Haven | E4: CT | F4: Northeast | G4: Roman Catholic | H4: 43959 | I4: Fall 2021 | K4: https://allsaintsnewhaven.org/ | L4: Formed from merging three New Haven Catholic elementary schools | M4: 4350 | N4: Catholic + Non Catholic Average | O4: https://allsaintsnewhaven.org/admissions/tuition | P4: 423 Ferry Street New Haven, CT 06513 | Q4: 91800 | R4: 2020
A5: =row()-1 -> 4 | B5: Chesterton Academy of Notre Dame | C5: https://www.spokesman.com/stories/2020/may/12/new-catholic-high-school-to-open-in-downtown-spoka/ | D5: Spokane | E5: WA | F5: West | G5: Roman Catholic | H5: 43963 | I5: Fall 2020 | J5: 160 | K5: https://chestertonacademyofnotredame.org/ | M5: 7500 | O5: https://chestertonacademyofnotredame.org/admissions | P5: 2706 E Queen Ave, Spokane, WA 99217 | Q5: 48986 | R5: 2020
A6: =row()-1 -> 5 | B6: Fairmont San Juan Capistrano | C6: https://www.prnewswire.com/news-releases/fairmont-schools-to-open-new-san-juan-capistrano-campus-301059547.html | D6: San Juan Capistrano | E6: CA | F6: West | G6: Independent | H6: 43965 | I6: Fall 2020 | J6: 850 | K6: https://www.fairmontschools.com/campuses/san-juan-capistrano-campus/ | M6: 22470 | O6: https://cdn.brandfolder.io/4N7CPF37/as/q05m7c-g0aw48-4bthtw/P12_Tuition__Fee_Information.pdf | P6: 26333 Oso Rd, San Juan Capistrano, CA 92675 | Q6: 52839 | R6: 2020
A7: =row()-1 -> 6 | B7: Gloria Deo Academy | C7: https://www.koamnewsnow.com/new-school-opening-in-joplin-provides-unique-combination-of-private-and-homeschool-education/ | D7: Joplin | E7: MO | F7: Midwest | G7: Christian | H7: 43970 | I7: Fall 2020 | K7: https://gloriadeoacademy.org/ | M7: 2880 | N7: 288 average/month for 10 months | O7: https://gloriadeoacademy.org/tuition-fees/ | P7: 600 E 50th St, Joplin, MO 64804 | Q7: 71238 | R7: 2020
A8: =row()-1 -> 7 | B8: Avenues Studio Hampton | C8: https://www.businessinsider.com/nyc-private-school-opening-hamptons-avenues-2020-5 | D8: New York City | E8: NY | F8: Northeast | G8: Independent | H8: 43979 | I8: Fall 2020 | J8: 150 | K8: https://www.avenues.org/ht/ | L8: Most classes online but some events in person | M8: 48000 | O8: https://www.businessinsider.com/nyc-private-school-opening-hamptons-avenues-2020-5 | P8: 11 Madison Square North New York, NY 10010-1420 | Q8: 268819
A9: =row()-1 -> 8 | B9: Fusion Academy | C9: https://www.wickedlocal.com/story/hingham-journal/2020/06/17/new-private-school-opens-in-hingham/42940191/ | D9: Hingham | E9: MA | F9: Northeast | G9: Independent | H9: 43999 | I9: Fall 2020 | J9: 60 | K9: https://www.fusionacademy.com/campuses/hingham/ | M9: 54150 | N9: 4512 average per middle school and high school class, 6 classes per term, two terms in a year | O9: https://www.fusionacademy.com/campuses/hingham/tuition/ | P9: 99 Derby Street Suite 103 Hingham, MA 02043 | Q9: 181357 | R9: 2020
A10: =row()-1 -> 9 | B10: Saint John Neumann Catholic School | C10: https://www.fox43.com/article/news/local/lancaster-county/saint-john-neumann-catholic-school-will-open-in-lancaster-this-fall-replacing-saint-anne-catholic/521-49beec85-2f6b-408c-9787-e5d7d11f7c3d | D10: Lancaster | E10: PA | F10: Northeast | G10: Roman Catholic | H10: 43999 | I10: Fall 2020 | K10: https://sjncslancaster.org/ | L10: replacing Saint Anne, which closed this year | M10: 4945 | N10: 4445 Catholic, 5445 non catholic | O10: https://sjncslancaster.org/admissions | P10: 601 E. Delp Road, Lancaster, PA 17601 | Q10: 88277 | R10: 2020
A11: =row()-1 -> 10 | B11: St. Joseph Academy | C11: https://www.stjosephacademy.com/ | D11: Hammonton | E11: NJ | F11: Northeast | G11: Roman Catholic | H11: 44089 | I11: Fall 2020 | J11: 150 | K11: https://www.nj.com/news/2020/09/shuttered-nj-catholic-school-revived-as-private-academy-by-alumni-supporters.html | L11: Opening as independent high school after St. Joseph Catholic High School was closed by diocese. | M11: 11000 | P11: 328 Vine Street Hammonton, New Jersey 08037 | Q11: 119663 | R11: 2020
A12: =row()-1 -> 11 | B12: Acton Academy Lincoln | C12: https://www.1011now.com/2020/09/22/new-school-opening-in-lincoln/ | D12: Lincoln | E12: NE | F12: Midwest | G12: Independent | H12: 44095 | I12: Fall 2020 | J12: 12 | K12: https://www.actonacademylincoln.com/ | M12: 7900 | N12: $500 discount if all paid upfront | O12: https://www.actonacademylincoln.com/faq.html | P12: 8400 Cody Drive ​Lincoln, NE 68512 | Q12: 97776 | R12: 2020
A13: =row()-1 -> 12 | B13: Brompton Community Center | C13: https://fredericksburg.com/news/local/fredericksburg-approves-new-private-school-at-braehead-manor/article_b01bac14-f92a-500e-82c9-3a6fb35861dc.html | D13: Fredericksburg | E13: VA | F13: South | G13: Independent | H13: 44209 | I13: Fall 2021 | K13: https://bromptoncommunityschool.org/ | M13: 12500 | O13: https://bromptoncommunityschool.org/admissions-tuition/ | P13: 123 Lee Dr, Fredericksburg, VA 22401 | Q13: 75291 | R13: 2020
A14: =row()-1 -> 13 | B14: Renaissance School | C14: https://communityimpact.com/dallas-fort-worth/mckinney/impacts/2021/01/26/new-mckinney-private-school-wont-require-algebra-or-calculus/ | D14: McKinney | E14: TX | F14: South | G14: Independent | H14: 44222 | I14: Fall 2022 | K14: https://therschool.org/ | L14: No address yet | M14: 12000 | O14: https://communityimpact.com/dallas-fort-worth/mckinney/impacts/2021/01/26/new-mckinney-private-school-wont-require-algebra-or-calculus/
A15: =row()-1 -> 14 | B15: Bear Town Academy | C15: https://www.witn.com/2021/03/10/new-elementary-school-to-open-in-new-bern/ | D15: New Bern | E15: NC | F15: South | G15: Independent | H15: 44265 | I15: Fall 2021 | K15: https://beartownacademy.com/ | P15: 1909 (B&C) S. Glenburnie Rd. New Bern, NC | Q15: 73582 | R15: 2020
A16: =row()-1 -> 15 | B16: Chesterton Academy of St. Mary's | C16: https://www.thebaynet.com/articles/0321/a-new-catholic-high-school-coming-to-st-marys-county.html | D16: Charlotte Hall | E16: MD | F16: South | G16: Roman Catholic | H16: 44271 | I16: Fall 2021 | J16: 25 | K16: https://www.chestertonstmarys.org/ | M16: 8500 | O16: https://www.chestertonstmarys.org/ | P16: 29530 Charlotte Hall Road, Charlotte Hall, MD 20622 | Q16: 105672 | R16: 2020
A17: =row()-1 -> 16 | B17: Stratford School | C17: https://www.pleasantonweekly.com/news/2021/03/29/new-middle-school-to-open-in-pleasanton-this-fall | D17: Pleasanton | E17: CA | F17: West | H17: 44284 | I17: Fall 2021
A18: =row()-1 -> 17 | B18: Acton Academy Sioux Falls | C18: https://www.keloland.com/news/education/new-acton-academy-private-school-opening-up-in-sioux-falls/ | D18: Sioux Falls | E18: SD | F18: Midwest | G18: Independent | H18: 44291 | I18: Fall 2021 | K18: https://www.actonacademysiouxfalls.org/ | M18: 7700 | N18: $700/month for 11 months | O18: https://www.actonacademysiouxfalls.org/faq | P18: 3628 S Southeastern Ave, Sioux Falls, SD 57103 | Q18: 91665 | R18: 2020
A19: =row()-1 -> 18 | B19: Thales Academy Flowers Plantation | C19: https://www.facebook.com/FlowersPlantationNC/posts/its-official-thales-academy-is-coming-to-flowers-plantation-slated-to-open-july-/4191352904216730/ | D19: Clayton | E19: NC | F19: South | G19: Independent | H19: 44291 | I19: Fall 2022 | K19: https://www.cbs17.com/news/local-news/thales-academy-to-open-1-new-campus-a-year-earlier-than-expected-heres-where/ | L19: Opened one year ahead of schedule | M19: 5400 | N19: Average of K-5 and 6-8 | O19: https://www.thalesacademy.org/admissions/tuition-information | P19: 65 Flowers Parkway Clayton, NC 27527 | Q19: 97566 | R19: 2021
A20: =row()-1 -> 19 | B20: The Linder Academy | C20: https://alexandrialivingmagazine.com/private-school-the-linder-academy-to-open-in-old-town/ | D20: Alexandria | E20: VA | F20: South | G20: Independent | H20: 44292 | I20: Fall 2021 | K20: https://www.thelinderacademy.com/ | M20: 28500 | O20: https://www.thelinderacademy.com/faqs | P20: Old Town location: 607 S Washington St, Alexandria, VA 22314 | Q20: Old Town: $264,867 | R20: 2020
A21: =row()-1 -> 20 | B21: Capstone Christian Academy | C21: https://www.reviewjournal.com/local/education/christian-school-plans-ivy-league-flavor-campus-in-southeast-valley-2326430/ | D21: Las Vegas | E21: NV | F21: West | G21: Christian | H21: 44296 | I21: Fall 2021 | J21: 144 | K21: https://www.capstonechristian.com/ | O21: https://www.capstonechristian.com/requesttuition | P21: 985 E Serene Ave, Las Vegas, NV 89123 | Q21: 72237 | R21: 2020
A22: =row()-1 -> 21 | B22: Thales Academy Greenville | C22: https://greenvillejournal.com/education/thales-academy-to-open-greenville-location-in-hartness-community/ | D22: Greenville | E22: NC | F22: South | G22: Independent | H22: 44314 | I22: Fall 2023 | K22: https://www.thalesacademy.org/ | L22: Applications open Sep. 2022 (No expected enrollment or campus address yet) | M22: 6000 | O22: https://www.thalesacademy.org/
A23: =row()-1 -> 22 | B23: Village School of South Orange | C23: https://www.tapinto.net/towns/soma/sections/education/articles/parents-to-launch-south-orange-maplewood-s-first-independent-elementary-school | D23: South Orange | E23: NJ | F23: Northeast | G23: Independent | H23: 44320 | I23: Fall 2021 | J23: Aiming for 30 the first few years, then to grow to over 100 | K23: https://villageschoolsouthorange.org/ | M23: 19500 | O23: https://villageschoolsouthorange.org/admission | P23: 111 Irvington Ave South Orange, NJ 07079 | Q23: 152395 | R23: 2020
A24: =row()-1 -> 23 | B24: Mother of Mercy Academy | C24: https://motherofmercyacademy.org/ | D24: Pittsburgh | E24: PA | F24: Northeast | G24: Roman Catholic | H24: 44335 | I24: Fall 2021 | K24: https://diopitt.org/news/new-names-announced-for-newly-merged-catholic-schools | P24: 5200 Greenridge Drive Pittsburgh, PA 15236 | Q24: 93081 | R24: 2020
A25: =row()-1 -> 24 | B25: Lazy H Ranch | C25: https://www.hmbreview.com/news/lazy-h-ranch-opens-new-private-school/article_02feb0ec-be38-11eb-9aa0-c32a40f6cf51.html | D25: Half Moon Bay | E25: CA | F25: West | G25: Independent | H25: 44342 | I25: Fall 2021 | J25: 16 | K25: https://www.littlehelementary.com/ | M25: 16000 | N25: $1600 month for 10 months | O25: https://www.littlehelementary.com/schedule-and-tuition | P25: 3100 Miramontes Point Road Half Moon Bay, Ca 94019 | Q25: 156963 | R25: 2020
A26: =row()-1 -> 25 | B26: FaithPrep Indiana | C26: https://in.chalkbeat.org/2021/6/1/22463572/vouchers-virtual-private-schools-indiana | D26: Virtual | E26: IN | F26: Midwest | G26: Christian | H26: 44348 | J26: 500 students expected for the first year, intends to expand to 2,500 over next 5 years | K26: https://in.chalkbeat.org/2021/6/1/22463572/vouchers-virtual-private-schools-indiana; https://www.in.gov/sboe/files/faithprep-indiana-seeking-accreditation-summary.pdf; https://www.faithprep.com/ | M26: 6750 | N26: $6,250 for elementary students/$7,250 for middle and high schoolers | O26: https://in.chalkbeat.org/2021/6/1/22463572/vouchers-virtual-private-schools-indiana
A27: =row()-1 -> 26 | B27: Geo Focus Academy | C27: https://in.chalkbeat.org/2021/6/1/22463572/vouchers-virtual-private-schools-indiana | D27: Virtual | E27: IN | F27: Midwest | G27: Independent | H27: 44348 | J27: Initially can enroll up to 700 students, intends to expand to 1,000 students over time | K27: https://www.in.gov/sboe/files/geo-focus-academy-seeking-accreditation-summary.docx.pdf; https://geoacademies.org/focus-academy/ | M27: 7000 | P27: 3145 N. Meridian St. Indianapolis, IN 46208 | Q27: 25313 | R27: 2020
A28: =row()-1 -> 27 | B28: Lumen Verum Academy | C28: https://www.patriotledger.com/story/news/2021/06/01/first-all-new-catholic-secondary-school-half-century-open/5287812001/ | D28: Boston | E28: MA | F28: Northeast | G28: Roman Catholic | H28: 44348 | I28: Fall 2021 | J28: 25 enrolled initially | K28: https://lumenverumacademy.org/ | M28: 14750 | P28: 66 Brooks Dr, Braintree, MA 02184 | Q28: 123020 | R28: 2020
A29: =row()-1 -> 28 | B29: Jean Charles Academy | C29: https://lynnjournal.com/2021/06/02/jean-charles-academy-an-accessible-dual-language-private-school-to-open-in-lynn/ | D29: Lynn | E29: MA | F29: Northeast | G29: Independent | H29: 44349 | I29: Fall 2021 | J29: Up to 40 first year, continuing to expand yearly until can offer a full K-12 program | K29: https://www.jeancharlesacademy.org/faqs | N29: JCA tuition is based on a shared economy structure. Families can choose to pay all of the tuition or contribute half of the cost via cash and the other half by sharing their time and/or talent with the school." | O29: https://www.jeancharlesacademy.org/faqs | P29: 498 Essex St Lynn, MA 01902 | Q29: 41723 | R29: 2020
A30: =row()-1 -> 29 | B30: Northeast Christian High School | C30: https://ktvo.com/news/local/new-christian-high-school-in-kirksville-hopes-for-big-changes-in-its-future | D30: Kirksville | E30: MO | F30: Midwest | G30: Christian | H30: 44354 | I30: Fall 2021 | N30: No tuition information available yet | O30: https://www.northeastchs.com/admissions-standards/tuition-fees | P30: 1702 N Elson St, Kirksville, MO 63501 | Q30: 41083 | R30: 2020
A31: =row()-1 -> 30 | B31: Yellowhab Norfolk | C31: https://www.pilotonline.com/news/education/vp-nw-pharrell-williams-yellowhab-school-20210607-hhyzrj6cmjg7pae4s77tqdl3ye-story.html | D31: Norfolk | E31: VA | F31: South | G31: Independent | H31: 44354 | I31: Fall 2021 | L31: School started by Pharell Williams' nonprofit; Cannot find address? | M31: 0 | N31: Tuition-free for at least the first year | O31: https://teamyellow.org/yellowhab
A32: =row()-1 -> 31 | B32: Evergreen Christian High School | C32: https://loudounnow.com/2021/06/10/evergreen-christian-high-school-eyes-fall-opening/ | D32: Leesburg | E32: VA | F32: South | G32: Christian | H32: 44357 | I32: Fall 2021 | M32: 17000 | P32: 21336 Evergreen Mills Rd, Leesburg, VA 20175 | Q32: 209779 | R32: 2020
A33: =row()-1 -> 32 | B33: Cedar School | C33: https://www.greenwichtime.com/local/article/Cedar-School-to-join-educational-landscape-in-16241434.php | D33: Greenwich | E33: CT | F33: Northeast | G33: Special needs | H33: 44358 | I33: Fall 2021 | J33: 25 students first year, maxiumum enrollment of 100 for following years | K33: https://www.thecedarschool.org/ | L33: School is for dyslexic/language-based learning difference students | M33: 47000 | O33: https://www.thecedarschool.org/admissions/tuition-and-fees.cfm | P33: 200 Pemberwick Rd Greenwich, CT 06831 | Q33: 122440 | R33: 2020
A34: =row()-1 -> 33 | B34: Shawnee Nazarene Academy | C34: https://shawneemissionpost.com/2021/06/28/shawnee-nazarene-academy-126016/ | D34: Shawnee | E34: KS | F34: Midwest | G34: Christian | H34: 44358 | I34: Fall 2021 | J34: Capacity is 50 students for now | K34: https://shawneenaz.org/shawnee-naz-academy | M34: 6630 | O34: https://umuhh8.nucleus.church/download/a18e823af076e1dd6516f4e26b3c3896298e3a48.pdf | P34: 5539 Quivira Rd Shawnee, KS 66203 | Q34: 58103 | R34: 2020
A35: =row()-1 -> 34 | B35: Arbor Academy | C35: https://communityimpact.com/austin/georgetown/education/2021/06/15/project-based-private-school-in-georgetown-now-enrolling-for-august-opening/ | D35: Georgetown | E35: TX | F35: South | G35: Independent | H35: 44362 | I35: Fall 2021 | K35: https://www.arboracademy.org/ | M35: 8700 | O35: https://www.arboracademy.org/enroll | P35: 412 E 19th St Georgetown, TX 78626 | Q35: 84688 | R35: 2020
A36: =row()-1 -> 35 | B36: Challenge Prepatory Academy | C36: https://www.wjbf.com/cyber/cyber-education-prep-school-opening-in-harrisburg-this-fall/ | D36: Augusta | E36: GA | F36: South | G36: Independent | H36: 44369 | I36: Fall 2021 | K36: https://www.challengeprepacademy.org/ | M36: 7500 | O36: https://www.challengeprepacademy.org/tuition | P36: 1948 Ellis St Augusta, GA 30904 | Q36: 27447 | R36: 2020
A37: =row()-1 -> 36 | B37: Catskill Wheelhouse Community | C37: https://www.hudsonvalley360.com/news/greenecounty/private-elementary-school-to-open-in-fall/article_8a0c7d79-6eec-500f-a668-fd3a543abe76.html | D37: Cairo | E37: NY | F37: Northeast | G37: Independent | H37: 44370 | I37: Fall 2021 | J37: 36 | K37: http://www.catskillwheelhouse.org/ | M37: 9000 | N37: Sliding scale based on need; ranges from 0 to 18,000 | O37: http://www.catskillwheelhouse.org/forest-school; http://www.catskillwheelhouse.org/community-school | P37: 665 Main St Cairo, NY 12413 | Q37: 70264 | R37: 2020
A38: =row()-1 -> 37 | B38: St. Catherine of Siena Academy | C38: https://www.wwnytv.com/2021/06/23/canton-sees-return-catholic-elementary-education/ | D38: Canton | E38: NY | F38: Northeast | G38: Roman Catholic | H38: 44370 | I38: Fall 2021 | K38: https://www.sienaacademy.org/ | M38: 4000 | O38: https://www.sienaacademy.org/faqs | P38: 2 Powers St, Canton, NY 13617 | Q38: 83093 | R38: 2020
A39: =row()-1 -> 38 | B39: Prairie Song Academy | C39: https://www.kirksvilledailyexpress.com/story/news/2021/07/07/prairie-song-academy-montessori-based-school-opening-kirksville-year/7842192002/ | D39: Kirksville | E39: MO | F39: Midwest | G39: Independent | H39: 44384 | I39: Fall 2021 | K39: https://prairiesongacademy.com/ | M39: 1406 | N39: Sliding tuition scale, average of 703.13/semester, two semesters in a year | O39: https://prairiesongacademy.com/enrollment/tuition/ | P39: 1301 E PATTERSON STREET KIRKSVILLE MO 63501 | Q39: 68446 | R39: 2020
A40: =row()-1 -> 39 | B40: Scenic City Montessori | C40: https://www.timesfreepress.com/news/local/story/2021/jul/25/two-new-montessori-schools-open-chattanoogare/550975/ | D40: Chattanooga | E40: TN | F40: South | G40: Independent | H40: 44402 | I40: Fall 2021 | J40: <30 | K40: https://www.themontessorischool.net/ | M40: 9125 | N40: 8801 K-5, 9449 6-8 | O40: https://www.themontessorischool.net/tuition-terms/ | P40: 6310 Dayton Blvd Hixson, TN 37343 | Q40: 78190 | R40: 2020
...

Sheet Openings_summary_since_aug_2025
A1: Openings | B1: Type
A2: Total | B2: Catholic | C2: Episcopal | D2: Lutheran | E2: Christian | F2: Jewish | G2: Special needs | H2: Ind.
A3: =COUNTIF(All_openings!H2:H1033, ">=8/1/2025") -> 65 | B3: =COUNTIFS(All_openings!H2:H1033, ">=8/1/2025",All_openings!G2:G1033, "Roman Catholic") -> 11 | C3: =COUNTIFS(All_openings!H2:H1033, ">=8/1/2025",All_openings!G2:G1033, "Episcopal") -> 0 | D3: =COUNTIFS(All_openings!H2:H1033, ">=8/1/2025",All_openings!G2:G1033, "Lutheran") -> 1 | E3: =COUNTIFS(All_openings!H2:H1033, ">=8/1/2025",All_openings!G2:G1033, "Christian") -> 13 | F3: =COUNTIFS(All_openings!H2:H1033, ">=8/1/2025",All_openings!G2:G1033, "Jewish") -> 3 | G3: =COUNTIFS(All_openings!H2:H1033, ">=8/1/2025",All_openings!G2:G1033, "Special needs") -> 4 | H3: =COUNTIFS(All_openings!H2:H1033, ">=8/1/2025",All_openings!G2:G1033, "Independent") -> 30

Sheet Openings_by_month_since_aug_202
B1: Number of Announced Openings
A2: =IF(EDATE(DATE(2025,6,1), row(A2))<TODAY(), EDATE(DATE(2025,6,1), Row(A2)), "") -> 45870 | B2: =IF(A2="","",COUNTIFS(All_openings!$H$2:$H$1034, ">="& EDATE(DATE(2025,6,1), row(A2)),All_openings!$H$2:$H$1034, "<"& EDATE(DATE(2025,7,1), row(A2)))) -> 9
A3: =IF(EDATE(DATE(2025,6,1), row(A3))<TODAY(), EDATE(DATE(2025,6,1), Row(A3)), "") -> 45901 | B3: =IF(A3="","",COUNTIFS(All_openings!$H$2:$H$1034, ">="& EDATE(DATE(2025,6,1), row(A3)),All_openings!$H$2:$H$1034, "<"& EDATE(DATE(2025,7,1), row(A3)))) -> 4
A4: =IF(EDATE(DATE(2025,6,1), row(A4))<TODAY(), EDATE(DATE(2025,6,1), Row(A4)), "") -> 45931 | B4: =IF(A4="","",COUNTIFS(All_openings!$H$2:$H$1034, ">="& EDATE(DATE(2025,6,1), row(A4)),All_openings!$H$2:$H$1034, "<"& EDATE(DATE(2025,7,1), row(A4)))) -> 1
A5: =IF(EDATE(DATE(2025,6,1), row(A5))<TODAY(), EDATE(DATE(2025,6,1), Row(A5)), "") -> 45962 | B5: =IF(A5="","",COUNTIFS(All_openings!$H$2:$H$1034, ">="& EDATE(DATE(2025,6,1), row(A5)),All_openings!$H$2:$H$1034, "<"& EDATE(DATE(2025,7,1), row(A5)))) -> 4
A6: =IF(EDATE(DATE(2025,6,1), row(A6))<TODAY(), EDATE(DATE(2025,6,1), Row(A6)), "") -> 45992 | B6: =IF(A6="","",COUNTIFS(All_openings!$H$2:$H$1034, ">="& EDATE(DATE(2025,6,1), row(A6)),All_openings!$H$2:$H$1034, "<"& EDATE(DATE(2025,7,1), row(A6)))) -> 0
A7: =IF(EDATE(DATE(2025,6,1), row(A7))<TODAY(), EDATE(DATE(2025,6,1), Row(A7)), "") -> 46023 | B7: =IF(A7="","",COUNTIFS(All_openings!$H$2:$H$1034, ">="& EDATE(DATE(2025,6,1), row(A7)),All_openings!$H$2:$H$1034, "<"& EDATE(DATE(2025,7,1), row(A7)))) -> 6
A8: =IF(EDATE(DATE(2025,6,1), row(A8))<TODAY(), EDATE(DATE(2025,6,1), Row(A8)), "") -> 46054 | B8: =IF(A8="","",COUNTIFS(All_openings!$H$2:$H$1034, ">="& EDATE(DATE(2025,6,1), row(A8)),All_openings!$H$2:$H$1034, "<"& EDATE(DATE(2025,7,1), row(A8)))) -> 7
A9: =IF(EDATE(DATE(2025,6,1), row(A9))<TODAY(), EDATE(DATE(2025,6,1), Row(A9)), "") -> 46082 | B9: =IF(A9="","",COUNTIFS(All_openings!$H$2:$H$1034, ">="& EDATE(DATE(2025,6,1), row(A9)),All_openings!$H$2:$H$1034, "<"& EDATE(DATE(2025,7,1), row(A9)))) -> 3
A10: =IF(EDATE(DATE(2025,6,1), row(A10))<TODAY(), EDATE(DATE(2025,6,1), Row(A10)), "") -> 46113 | B10: =IF(A10="","",COUNTIFS(All_openings!$H$2:$H$1034, ">="& EDATE(DATE(2025,6,1), row(A10)),All_openings!$H$2:$H$1034, "<"& EDATE(DATE(2025,7,1), row(A10)))) -> 6
A11: =IF(EDATE(DATE(2025,6,1), row(A11))<TODAY(), EDATE(DATE(2025,6,1), Row(A11)), "") -> 46143 | B11: =IF(A11="","",COUNTIFS(All_openings!$H$2:$H$1034, ">="& EDATE(DATE(2025,6,1), row(A11)),All_openings!$H$2:$H$1034, "<"& EDATE(DATE(2025,7,1), row(A11)))) -> 10
A12: =IF(EDATE(DATE(2025,6,1), row(A12))<TODAY(), EDATE(DATE(2025,6,1), Row(A12)), "") -> 46174 | B12: =IF(A12="","",COUNTIFS(All_openings!$H$2:$H$1034, ">="& EDATE(DATE(2025,6,1), row(A12)),All_openings!$H$2:$H$1034, "<"& EDATE(DATE(2025,7,1), row(A12)))) -> 10
A13: =IF(EDATE(DATE(2025,6,1), row(A13))<TODAY(), EDATE(DATE(2025,6,1), Row(A13)), "") -> 46204 | B13: =IF(A13="","",COUNTIFS(All_openings!$H$2:$H$1034, ">="& EDATE(DATE(2025,6,1), row(A13)),All_openings!$H$2:$H$1034, "<"& EDATE(DATE(2025,7,1), row(A13)))) -> 5
A14: =IF(EDATE(DATE(2025,6,1), row(A14))<TODAY(), EDATE(DATE(2025,6,1), Row(A14)), "") | B14: =IF(A14="","",COUNTIFS(All_openings!$H$2:$H$1034, ">="& EDATE(DATE(2025,6,1), row(A14)),All_openings!$H$2:$H$1034, "<"& EDATE(DATE(2025,7,1), row(A14))))

Sheet cs_aug_2022
A1: Closures | B1: Type | I1: Total Enroll. | J1: Avg. Enroll. | K1: Avg. Tuition
B2: Catholic | C2: Episcopal | D2: Lutheran | E2: Christian | F2: Jewish | G2: Special needs | H2: Ind.
A3: =COUNTIF(All_closures!J2:J1005, ">=8/1/2022") -> 234 | B3: =COUNTIFS(All_closures!J2:J1005, ">=8/1/2022",All_closures!I2:I1005, "Roman Catholic") -> 178 | C3: =COUNTIFS(All_closures!J2:J1005, ">=8/1/2022",All_closures!I2:I1005, "Episcopal") -> 1 | D3: =COUNTIFS(All_closures!J2:J1005, ">=8/1/2022",All_closures!I2:I1005, "Lutheran") -> 1 | E3: =COUNTIFS(All_closures!J2:J1005, ">=8/1/2022",All_closures!I2:I1005, "Christian") -> 17 | F3: =COUNTIFS(All_closures!J2:J1005, ">=8/1/2022",All_closures!I2:I1005, "Jewish") -> 3 | G3: =COUNTIFS(All_closures!J2:J1005, ">=8/1/2022",All_closures!I2:I1005, "Special needs") -> 3 | H3: =COUNTIFS(All_closures!J2:J1005, ">=8/1/2022",All_closures!I2:I1005, "Independent") -> 30 | I3: =SUMIF(All_closures!J2:J1005, ">=8/1/2022", All_closures!K2:K1005) -> 33878 | J3: =SUMIF(All_closures!J2:J1005, ">=8/1/2022", All_closures!K2:K1005)/A3 -> 144.77778 | K3: =AVERAGEIF(All_closures!J2:J1005, ">=8/1/2022", All_closures!S2:S1005) -> 10036.167

Sheet cs_aug_2023
A1: Closures | B1: Type | I1: Total Enroll. | J1: Avg. Enroll. | K1: Avg. Tuition
B2: Catholic | C2: Episcopal | D2: Lutheran | E2: Christian | F2: Jewish | G2: Special needs | H2: Ind.
A3: =COUNTIFS(All_closures!J2:J1005, ">=8/1/2023", All_closures!J2:J1005, "<=7/31/2024") -> 60 | B3: =COUNTIFS(All_closures!J2:J1005, ">=8/1/2023",All_closures!J2:J1005, "<8/1/2024",All_closures!I2:I1005, "Roman Catholic") -> 41 | C3: =COUNTIFS(All_closures!J2:J1005, ">=8/1/2023", All_closures!J2:J1005, "<8/1/2024", All_closures!I2:I1005, "Episcopal") -> 0 | D3: =COUNTIFS(All_closures!J2:J1005, ">=8/1/2023", All_closures!J2:J1005, "<8/1/2024",All_closures!I2:I1005, "Lutheran") -> 0 | E3: =COUNTIFS(All_closures!J2:J1005, ">=8/1/2023", All_closures!J2:J1005, "<8/1/2024",All_closures!I2:I1005, "Christian") -> 8 | F3: =COUNTIFS(All_closures!J2:J1005, ">=8/1/2023", All_closures!J2:J1005, "<8/1/2024",All_closures!I2:I1005, "Jewish") -> 1 | G3: =COUNTIFS(All_closures!J2:J1005, ">=8/1/2023", All_closures!J2:J1005, "<8/1/2024",All_closures!I2:I1005, "Special needs") -> 1 | H3: =COUNTIFS(All_closures!J2:J1005, ">=8/1/2023", All_closures!J2:J1005, "<8/1/2024",All_closures!I2:I1005, "Independent") -> 9 | I3: =SUMIFS(All_closures!K2:K1005, All_closures!J2:J1005, ">=8/1/2023", All_closures!J2:J1005, "<=7/31/2024") -> 6572 | J3: =if(A3=0,"", SUMIFS(All_closures!K2:K1005, All_closures!J2:J1005, ">=8/1/2023", All_closures!J2:J1005, "<=7/31/2024")/A3) -> 109.53333 | K3: =if(A3=0,"",AVERAGEIFS(All_closures!S2:S1005, All_closures!J2:J1005, ">=8/1/2023", All_closures!J2:J1005, "<=7/31/2024")) -> 10835.535

Sheet cs_aug_2024
A1: Closures | B1: Type | I1: Total Enroll. | J1: Avg. Enroll. | K1: Avg. Tuition
B2: Catholic | C2: Episcopal | D2: Lutheran | E2: Christian | F2: Jewish | G2: Special needs | H2: Ind.
A3: =COUNTIF(All_closures!J2:J1005, ">=8/1/2024") -> 120 | B3: =COUNTIFS(All_closures!J2:J1005, ">=8/1/2024",All_closures!I2:I1005, "Roman Catholic") -> 92 | C3: =COUNTIFS(All_closures!J2:J1005, ">=8/1/2024",All_closures!I2:I1005, "Episcopal") -> 1 | D3: =COUNTIFS(All_closures!J2:J1005, ">=8/1/2024",All_closures!I2:I1005, "Lutheran") -> 1 | E3: =COUNTIFS(All_closures!J2:J1005, ">=8/1/2024",All_closures!I2:I1005, "Christian") -> 8 | F3: =COUNTIFS(All_closures!J2:J1005, ">=8/1/2024",All_closures!I2:I1005, "Jewish") -> 2 | G3: =COUNTIFS(All_closures!J2:J1005, ">=8/1/2024",All_closures!I2:I1005, "Special needs") -> 1 | H3: =COUNTIFS(All_closures!J2:J1005, ">=8/1/2024",All_closures!I2:I1005, "Independent") -> 14 | I3: =SUMIF(All_closures!J2:J1005, ">=8/1/2024", All_closures!K2:K1005) -> 17682 | J3: =if(A3=0,"", SUMIF(All_closures!J2:J1005, ">=8/1/2024", All_closures!K2:K1005)/A3) -> 147.35 | K3: =if(A3=0,"",AVERAGEIF(All_closures!J2:J1005, ">=8/1/2024", All_closures!S2:S1005)) -> 9637.8

Sheet All_closures
B1: Closures | C1: COVID? | D1: Merging with Other School Closure | E1: New School | F1: Town | G1: State | H1: Region | I1: Type | J1: Date Reported | K1: Enrollment | L1: Enrollment source | M1: Year founded | N1: Notes | O1: Preexisting financial problems? | P1: Link | Q1: % Students on Financial Aid | R1: Link2 | S1: Tuition | T1: Link3 | U1: % Black | V1: Enrolled Black | W1: % Hispanic | X1: Enrolled Hispanic | Y1: % Asian | Z1: Enrolled Asian | AA1: % White | AB1: Enrolled White | AC1: % Other | AD1: Enrolled Other | AE1: Link4 | AF1: Full Address | AG1: Estimated Tract Median Family Income | AH1: Data Year
A2: =ROW()-1 -> 1 | B2: Saint Anthony School | C2: x | F2: Winsted | G2: CT | H2: Northeast | I2: Roman Catholic | J2: 43908 | K2: 90 | L2: Media | M2: 1865 | O2: Yes | P2: https://www.registercitizen.com/news/article/Winsted-s-St-Anthony-School-closing-in-June-15138379.php | S2: 5200 | T2: http://www.stanthonyschool-winsted.org/wp-content/uploads/2019/03/FullSizeRender-2019-03-28T205251.691.jpg | U2: 0 | V2: =IF(U2<>"",K2*U2/100,"") -> 0 | W2: 0 | X2: =IF(W2<>"",K2*W2/100,"") -> 0 | Y2: 1.8 | Z2: =IF(Y2<>"",K2*Y2/100,"") -> 1.62 | AA2: 95.8 | AB2: =IF(AA2<>"",K2*AA2/100,"") -> 86.22 | AC2: 2.4 | AD2: =IF(AC2<>"",K2*AC2/100,"") -> 2.16 | AE2: https://www.niche.com/k12/st-anthony-school-winsted-ct/ | AF2: 55 Oak St, Winsted, CT 06098 | AG2: 59763 | AH2: 2020
A3: =ROW()-1 -> 2 | B3: Midreshet Shalhevet High School | C3: x | F3: Valley Stream | G3: NY | H3: Northeast | I3: Jewish | J3: 43922 | K3: 80 | L3: PSR | M3: 2007 | U3: 0 | V3: =IF(U3<>"",K3*U3/100,"") -> 0 | W3: 0 | X3: =IF(W3<>"",K3*W3/100,"") -> 0 | Y3: 0 | Z3: =IF(Y3<>"",K3*Y3/100,"") -> 0 | AA3: 100 | AB3: =IF(AA3<>"",K3*AA3/100,"") -> 80 | AC3: 0 | AD3: =IF(AC3<>"",K3*AC3/100,"") -> 0 | AE3: https://www.niche.com/k12/midreshet-shalhevet-shalhevet-high-school-for-girls-valley-stream-ny/students/ | AF3: 1000 Rosedale Rd, Valley Stream, NY 11581 | AG3: 136424 | AH3: 2020
A4: =ROW()-1 -> 3 | B4: Saint Martha | C4: x | F4: Enfield | G4: CT | H4: Northeast | I4: Roman Catholic | J4: 43929 | K4: 148 | L4: Media | M4: 1963 | N4: Parent group trying to save school | O4: Yes | P4: https://www.journalinquirer.com/towns/enfield/it-s-a-tragedy-for-everybody-st-martha-school-to-close-after-55-years-due/article_34e5607e-7f14-11ea-af3a-6f63e01e8aef.html | S4: 6303 | T4: https://www.stmarthaschool-ct.org/tuition | U4: 1.9 | V4: =IF(U4<>"",K4*U4/100,"") -> 2.812 | W4: 3.1 | X4: =IF(W4<>"",K4*W4/100,"") -> 4.588 | Y4: 6.2 | Z4: =IF(Y4<>"",K4*Y4/100,"") -> 9.176 | AA4: 85.7 | AB4: =IF(AA4<>"",K4*AA4/100,"") -> 126.836 | AC4: 3.1 | AD4: =IF(AC4<>"",K4*AC4/100,"") -> 4.588 | AE4: https://www.niche.com/k12/st-martha-school-enfield-ct/ | AF4: 214 Brainard Rd, Enfield, CT 06082 | AG4: 100538 | AH4: 2020
A5: =ROW()-1 -> 4 | B5: Oyster Point Academy | C5: x | F5: Hampton Roads | G5: VA | H5: South | I5: Special needs | J5: 43932 | K5: 28 | L5: PSR | U5: 82 | V5: =IF(U5<>"",K5*U5/100,"") -> 22.96 | W5: 4 | X5: =IF(W5<>"",K5*W5/100,"") -> 1.12 | Y5: 0 | Z5: =IF(Y5<>"",K5*Y5/100,"") -> 0 | AA5: 14 | AB5: =IF(AA5<>"",K5*AA5/100,"") -> 3.92 | AC5: 0 | AD5: =IF(AC5<>"",K5*AC5/100,"") -> 0 | AE5: https://high-schools.com/directory/va/cities/newport-news/oyster-point-academy/a1503976/ | AF5: 766 J Clyde Morris Blvd Newport News, VA 23601 | AG5: 72189 | AH5: 2020
A6: =ROW()-1 -> 5 | B6: Coyle and Cassidy H.S. & M.S. | C6: x | F6: Taunton | G6: MA | H6: Northeast | I6: Roman Catholic | J6: 43936 | K6: 258 | L6: Media | M6: 1911 | N6: Some dispute closure necessary or COVID-driven | O6: Yes | P6: https://www.tauntongazette.com/news/20200418/we-had-no-opportunity-to-save-that-school----coyle-cassidy-closure-in-taunton-draws-strong-reaction | S6: 10590 | T6: https://www.coylecassidy.com/tuition-rates-and-financial-aid/ | U6: 7.1 | V6: =IF(U6<>"",K6*U6/100,"") -> 18.318 | W6: 1.6 | X6: =IF(W6<>"",K6*W6/100,"") -> 4.128 | Y6: 2.6 | Z6: =IF(Y6<>"",K6*Y6/100,"") -> 6.708 | AA6: 88.3 | AB6: =IF(AA6<>"",K6*AA6/100,"") -> 227.814 | AC6: 0.4 | AD6: =IF(AC6<>"",K6*AC6/100,"") -> 1.032 | AE6: https://www.niche.com/k12/coyle--and--cassidy-high-school-taunton-ma/students/ | AF6: 2 Hamilton St, Taunton, MA 02780 | AG6: 63252 | AH6: 2020
A7: =ROW()-1 -> 6 | B7: Saint Margaret Primary | C7: x | F7: Buzzards Bay | G7: MA | H7: Northeast | I7: Roman Catholic | J7: 43936 | K7: 62 | L7: Media | M7: 1994 | O7: Yes | P7: http://www.smrsbb.org/wp-content/uploads/Two-School-Closures_April-14-2020.docx.pdf | Q7: 10 | R7: https://www.privateschoolreview.com/st-margaret-primary-school-profile | S7: 5825 | T7: http://www.smrsbb.org/wp-content/uploads/Enrollment-Information-2019-2020.pdf | U7: 5.3 | V7: =IF(U7<>"",K7*U7/100,"") -> 3.286 | W7: 4 | X7: =IF(W7<>"",K7*W7/100,"") -> 2.48 | Y7: 5.3 | Z7: =IF(Y7<>"",K7*Y7/100,"") -> 3.286 | AA7: 82.7 | AB7: =IF(AA7<>"",K7*AA7/100,"") -> 51.274 | AC7: 2.7 | AD7: =IF(AC7<>"",K7*AC7/100,"") -> 1.674 | AE7: https://www.niche.com/k12/st-margaret-primary-school-buzzards-bay-ma/ | AF7: 143 Main Street Buzzards Bay, MA 02532 | AG7: 122991 | AH7: 2020
